<?xml version='1.0'?>
<sdf version='1.4'>
  <model name="lgp_car">
        <static>false</static>

	<link name='chassis'>
            <pose>1.25 0 0.69 0 0 0</pose>

	      <inertial>
		<mass>100.0</mass>
	      </inertial>

            <collision name='collision'>
              <geometry>
                <box>
                  <size>4.3 1.7 1.0</size>
                </box>
              </geometry>

                  <surface>
		    <friction>
		      <ode>
		        <mu>0</mu>
		        <mu2>0</mu2>
		      </ode>
		    </friction>
		  </surface>

            </collision>

     	    
            <visual name='visual'>
              <geometry>
                <box>
                  <size>4.3 1.7 1.0</size>
                </box>
              </geometry>
            </visual>

             <collision name='caster_collision_left'>
		  <pose>1.4 0.9 -0.5 0 0 0</pose>
		    <geometry>
		      <sphere>
		      <radius>.19</radius>
		    </sphere>
		  </geometry>

		  <surface>
		    <friction>
		      <ode>
		        <mu>0</mu>
		        <mu2>0</mu2>
		        <slip1>0.0</slip1>
		        <slip2>0.0</slip2>
		      </ode>
		    </friction>
		  </surface>
		</collision>


		<visual name='caster_visual_left'>
		  <pose>1.4 0.9 -0.5 0 0 0</pose>
		  <geometry>
		    <sphere>
		      <radius>.19</radius>
		    </sphere>
		  </geometry>
		</visual>


                <collision name='caster_collision_right'>
		  <pose>1.4 -0.9 -0.5 0 0 0</pose>
		    <geometry>
		      <sphere>
		      <radius>.19</radius>
		    </sphere>
		  </geometry>

		  <surface>
		    <friction>
		      <ode>
		        <mu>0</mu>
		        <mu2>0</mu2>
		        <slip1>0.0</slip1>
		        <slip2>0.0</slip2>
		      </ode>
		    </friction>
		  </surface>
		</collision>


		<visual name='caster_visual_right'>
		  <pose>1.4 -0.9 -0.5 0 0 0</pose>
		  <geometry>
		    <sphere>
		      <radius>.19</radius>
		    </sphere>
		  </geometry>
		</visual>
          </link>


	<link name="left_wheel">
        <pose>0.0 0.9 0.19 0 1.5707 1.5707</pose>
		<collision name="collision">

		  <geometry>
		    <cylinder>
		      <radius>.19</radius>
		      <length>.05</length>
		    </cylinder>
		  </geometry>

                  <surface>
		    <friction>
		      <ode>
		        <mu>1000.00</mu>
		        <mu2>1000.00</mu2>
		      </ode>
		    </friction>
		  </surface>

		</collision>
		<visual name="visual">
		  <geometry>
		    <cylinder>
		      <radius>.19</radius>
		      <length>.05</length>
		    </cylinder>
		  </geometry>
		</visual>
     	 </link>

	<link name="right_wheel">
        <pose>0.0 -0.9 0.19 0 1.5707 1.5707</pose>
		<collision name="collision">
		  <geometry>
		    <cylinder>
		      <radius>.19</radius>
		      <length>.05</length>
		    </cylinder>
		  </geometry>
                  <surface>
		    <friction>
		      <ode>
		        <mu>1000.0</mu>
		        <mu2>1000.0</mu2>
		      </ode>
		    </friction>
		  </surface>

		</collision>
		<visual name="visual">
		  <geometry>
		    <cylinder>
		      <radius>.19</radius>
		      <length>.05</length>
		    </cylinder>
		  </geometry>
		</visual>
     	 </link>

	<joint type="revolute" name="left_wheel_hinge">
          <pose>0 0 -0.03 0 0 0</pose>
          <child>left_wheel</child>
          <parent>chassis</parent>
          <axis>
          <xyz>0 1 0</xyz>
          </axis>
      	</joint>

      	<joint type="revolute" name="right_wheel_hinge">
          <pose>0 0 0.03 0 0 0</pose>
          <child>right_wheel</child>
          <parent>chassis</parent>
          <axis>
          <xyz>0 1 0</xyz>
          </axis>
      	</joint>
	
  </model>
</sdf>
